Workbook

Sheet Data KE BRI
A2: ='Data Base Bule'!R2 -> Nomor Rekening | B2: =CONCATENATE('Data Base Bule'!R2,"|",'Data Base Bule'!C2,"|",'Data Base Bule'!S2,"|",'Data Base Bule'!T2,"|",'Data Base Bule'!U2,"|","|","ID","|","|","ID","|","|") -> Nomor Rekening|Bill To (Payer)|Alamat payer|Kota Payer|Negara Payer||ID||ID|| | C2: =CONCATENATE('Data Base Bule'!B2,"|",'Data Base Bule'!N2,"|",'Data Base Bule'!H2) -> Date of Transaction|Currency |Amounts | D2: ='Data Base Bule'!E2 -> Account number of Beneficiary | E2: =CONCATENATE('Data Base Bule'!D2,"|",'Data Base Bule'!K2,"#",'Data Base Bule'!J2,"#",'Data Base Bule'!I2) -> Beneficiary Name|Complete Address of Beneficiary Account#City of Beneficiary #Country of Beneficiary | F2: =CONCATENATE("A","|","|",'Data Base Bule'!L2) -> A||Swift | G2: N/A | H2: =CONCATENATE('Data Base Bule'!M2,"###") -> Payment details 1 ### | I2: OUR | J2: E0|N|199 | K2: N/A | L2: N/A
A3: ='Data Base Bule'!R4 -> 0 | B3: =CONCATENATE('Data Base Bule'!R4,"|",'Data Base Bule'!C4,"|",'Data Base Bule'!S4,"|",'Data Base Bule'!T4,"|",'Data Base Bule'!U4,"|","|","ID","|","|","ID","|","|") -> ||||||ID||ID|| | C3: =CONCATENATE('Data Base Bule'!B4,"|",'Data Base Bule'!N4,"|",'Data Base Bule'!H4) -> 260701|| | D3: ='Data Base Bule'!E4 -> 0 | E3: =CONCATENATE('Data Base Bule'!D4,"|",'Data Base Bule'!K4,"#",'Data Base Bule'!J4,"#",'Data Base Bule'!I4) -> |## | F3: =CONCATENATE("A","|","|",'Data Base Bule'!L4) -> A|| | G3: N/A | H3: =CONCATENATE('Data Base Bule'!M4,"###") -> ### | I3: OUR | J3: E0|N|199 | K3: N/A | L3: N/A | M3: remit.service09@gmail.com | N3: 1
A4: ='Data Base Bule'!R5 -> 0 | B4: =CONCATENATE('Data Base Bule'!R5,"|",'Data Base Bule'!C5,"|",'Data Base Bule'!S5,"|",'Data Base Bule'!T5,"|",'Data Base Bule'!U5,"|","|","ID","|","|","ID","|","|") -> ||||||ID||ID|| | C4: =CONCATENATE('Data Base Bule'!B5,"|",'Data Base Bule'!N5,"|",'Data Base Bule'!H5) -> 260701|| | D4: ='Data Base Bule'!E5 -> 0 | E4: =CONCATENATE('Data Base Bule'!D5,"|",'Data Base Bule'!K5,"#",'Data Base Bule'!J5,"#",'Data Base Bule'!I5) -> |## | F4: =CONCATENATE("A","|","|",'Data Base Bule'!L5) -> A|| | G4: N/A | H4: =CONCATENATE('Data Base Bule'!M5,"###") -> ### | I4: OUR | J4: E0|N|199 | K4: N/A | L4: N/A | M4: remit.service09@gmail.com | N4: 2
A5: ='Data Base Bule'!R6 -> 0 | B5: =CONCATENATE('Data Base Bule'!R6,"|",'Data Base Bule'!C6,"|",'Data Base Bule'!S6,"|",'Data Base Bule'!T6,"|",'Data Base Bule'!U6,"|","|","ID","|","|","ID","|","|") -> ||||||ID||ID|| | C5: =CONCATENATE('Data Base Bule'!B6,"|",'Data Base Bule'!N6,"|",'Data Base Bule'!H6) -> 260701|| | D5: ='Data Base Bule'!E6 -> 0 | E5: =CONCATENATE('Data Base Bule'!D6,"|",'Data Base Bule'!K6,"#",'Data Base Bule'!J6,"#",'Data Base Bule'!I6) -> |## | F5: =CONCATENATE("A","|","|",'Data Base Bule'!L6) -> A|| | G5: N/A | H5: =CONCATENATE('Data Base Bule'!M6,"###") -> ### | I5: OUR | J5: E0|N|199 | K5: N/A | L5: N/A | M5: remit.service09@gmail.com | N5: 3
A6: ='Data Base Bule'!R7 -> 0 | B6: =CONCATENATE('Data Base Bule'!R7,"|",'Data Base Bule'!C7,"|",'Data Base Bule'!S7,"|",'Data Base Bule'!T7,"|",'Data Base Bule'!U7,"|","|","ID","|","|","ID","|","|") -> ||||||ID||ID|| | C6: =CONCATENATE('Data Base Bule'!B7,"|",'Data Base Bule'!N7,"|",'Data Base Bule'!H7) -> 260701|| | D6: ='Data Base Bule'!E7 -> 0 | E6: =CONCATENATE('Data Base Bule'!D7,"|",'Data Base Bule'!K7,"#",'Data Base Bule'!J7,"#",'Data Base Bule'!I7) -> |## | F6: =CONCATENATE("A","|","|",'Data Base Bule'!L7) -> A|| | G6: N/A | H6: =CONCATENATE('Data Base Bule'!M7,"###") -> ### | I6: OUR | J6: E0|N|199 | K6: N/A | L6: N/A | M6: remit.service09@gmail.com | N6: 4
A7: ='Data Base Bule'!R8 -> 0 | B7: =CONCATENATE('Data Base Bule'!R8,"|",'Data Base Bule'!C8,"|",'Data Base Bule'!S8,"|",'Data Base Bule'!T8,"|",'Data Base Bule'!U8,"|","|","ID","|","|","ID","|","|") -> ||||||ID||ID|| | C7: =CONCATENATE('Data Base Bule'!B8,"|",'Data Base Bule'!N8,"|",'Data Base Bule'!H8) -> 260701|| | D7: ='Data Base Bule'!E8 -> 0 | E7: =CONCATENATE('Data Base Bule'!D8,"|",'Data Base Bule'!K8,"#",'Data Base Bule'!J8,"#",'Data Base Bule'!I8) -> |## | F7: =CONCATENATE("A","|","|",'Data Base Bule'!L8) -> A|| | G7: N/A | H7: =CONCATENATE('Data Base Bule'!M8,"###") -> ### | I7: OUR | J7: E0|N|199 | K7: N/A | L7: N/A | M7: remit.service09@gmail.com | N7: 5
A8: ='Data Base Bule'!R9 -> 0 | B8: =CONCATENATE('Data Base Bule'!R9,"|",'Data Base Bule'!C9,"|",'Data Base Bule'!S9,"|",'Data Base Bule'!T9,"|",'Data Base Bule'!U9,"|","|","ID","|","|","ID","|","|") -> ||||||ID||ID|| | C8: =CONCATENATE('Data Base Bule'!B9,"|",'Data Base Bule'!N9,"|",'Data Base Bule'!H9) -> 260701|| | D8: ='Data Base Bule'!E9 -> 0 | E8: =CONCATENATE('Data Base Bule'!D9,"|",'Data Base Bule'!K9,"#",'Data Base Bule'!J9,"#",'Data Base Bule'!I9) -> |## | F8: =CONCATENATE("A","|","|",'Data Base Bule'!L9) -> A|| | G8: N/A | H8: =CONCATENATE('Data Base Bule'!M9,"###") -> ### | I8: OUR | J8: E0|N|199 | K8: N/A | L8: N/A | M8: remit.service09@gmail.com | N8: 6
A9: ='Data Base Bule'!R10 -> 0 | B9: =CONCATENATE('Data Base Bule'!R10,"|",'Data Base Bule'!C10,"|",'Data Base Bule'!S10,"|",'Data Base Bule'!T10,"|",'Data Base Bule'!U10,"|","|","ID","|","|","ID","|","|") -> ||||||ID||ID|| | C9: =CONCATENATE('Data Base Bule'!B10,"|",'Data Base Bule'!N10,"|",'Data Base Bule'!H10) -> || | D9: ='Data Base Bule'!E10 -> 0 | E9: =CONCATENATE('Data Base Bule'!D10,"|",'Data Base Bule'!K10,"#",'Data Base Bule'!J10,"#",'Data Base Bule'!I10) -> |## | F9: =CONCATENATE("A","|","|",'Data Base Bule'!L10) -> A|| | G9: A||PNBPUS3NNYC | H9: =CONCATENATE('Data Base Bule'!M10,"###") -> ### | I9: OUR | J9: E0|N|199 | K9: N/A | L9: N/A | M9: remit.service09@gmail.com
A10: ='Data Base Bule'!R11 -> 0 | B10: =CONCATENATE('Data Base Bule'!R11,"|",'Data Base Bule'!C11,"|",'Data Base Bule'!S11,"|",'Data Base Bule'!T11,"|",'Data Base Bule'!U11,"|","|","ID","|","|","ID","|","|") -> ||||||ID||ID|| | C10: =CONCATENATE('Data Base Bule'!B11,"|",'Data Base Bule'!N11,"|",'Data Base Bule'!H11) -> || | D10: ='Data Base Bule'!E11 -> 0 | E10: =CONCATENATE('Data Base Bule'!D11,"|",'Data Base Bule'!K11,"#",'Data Base Bule'!J11,"#",'Data Base Bule'!I11) -> |## | F10: =CONCATENATE("A","|","|",'Data Base Bule'!L11) -> A|| | G10: N/A | H10: =CONCATENATE('Data Base Bule'!M11,"###") -> ### | I10: OUR | J10: E0|N|199 | K10: N/A | L10: N/A | M10: remit.service09@gmail.com
A11: ='Data Base Bule'!R12 -> 0 | B11: =CONCATENATE('Data Base Bule'!R12,"|",'Data Base Bule'!C12,"|",'Data Base Bule'!S12,"|",'Data Base Bule'!T12,"|",'Data Base Bule'!U12,"|","|","ID","|","|","ID","|","|") -> ||||||ID||ID|| | C11: =CONCATENATE('Data Base Bule'!B12,"|",'Data Base Bule'!N12,"|",'Data Base Bule'!H12) -> || | D11: ='Data Base Bule'!E12 -> 0 | E11: =CONCATENATE('Data Base Bule'!D12,"|",'Data Base Bule'!K12,"#",'Data Base Bule'!J12,"#",'Data Base Bule'!I12) -> |## | F11: =CONCATENATE("A","|","|",'Data Base Bule'!L12) -> A|| | G11: N/A | H11: =CONCATENATE('Data Base Bule'!M12,"###") -> ### | I11: OUR | J11: E0|N|199 | K11: N/A | L11: N/A | M11: remit.service09@gmail.com
A12: ='Data Base Bule'!R13 -> 0 | B12: =CONCATENATE('Data Base Bule'!R13,"|",'Data Base Bule'!C13,"|",'Data Base Bule'!S13,"|",'Data Base Bule'!T13,"|",'Data Base Bule'!U13,"|","|","ID","|","|","ID","|","|") -> ||||||ID||ID|| | C12: =CONCATENATE('Data Base Bule'!B13,"|",'Data Base Bule'!N13,"|",'Data Base Bule'!H13) -> || | D12: ='Data Base Bule'!E13 -> 0 | E12: =CONCATENATE('Data Base Bule'!D13,"|",'Data Base Bule'!K13,"#",'Data Base Bule'!J13,"#",'Data Base Bule'!I13) -> |## | F12: =CONCATENATE("A","|","|",'Data Base Bule'!L13) -> A|| | G12: N/A | H12: =CONCATENATE('Data Base Bule'!M13,"###") -> ### | I12: OUR | J12: E0|N|199 | K12: N/A | L12: N/A | M12: remit.service09@gmail.com
A13: ='Data Base Bule'!R14 -> 0 | B13: =CONCATENATE('Data Base Bule'!R14,"|",'Data Base Bule'!C14,"|",'Data Base Bule'!S14,"|",'Data Base Bule'!T14,"|",'Data Base Bule'!U14,"|","|","ID","|","|","ID","|","|") -> ||||||ID||ID|| | C13: =CONCATENATE('Data Base Bule'!B14,"|",'Data Base Bule'!N14,"|",'Data Base Bule'!H14) -> || | D13: ='Data Base Bule'!E14 -> 0 | E13: =CONCATENATE('Data Base Bule'!D14,"|",'Data Base Bule'!K14,"#",'Data Base Bule'!J14,"#",'Data Base Bule'!I14) -> |## | F13: =CONCATENATE("A","|","|",'Data Base Bule'!L14) -> A|| | G13: N/A | H13: =CONCATENATE('Data Base Bule'!M14,"###") -> ### | I13: OUR | J13: E0|N|199 | K13: N/A | L13: N/A | M13: remit.service09@gmail.com
A14: ='Data Base Bule'!R15 -> 0 | B14: =CONCATENATE('Data Base Bule'!R15,"|",'Data Base Bule'!C15,"|",'Data Base Bule'!S15,"|",'Data Base Bule'!T15,"|",'Data Base Bule'!U15,"|","|","ID","|","|","ID","|","|") -> ||||||ID||ID|| | C14: =CONCATENATE('Data Base Bule'!B15,"|",'Data Base Bule'!N15,"|",'Data Base Bule'!H15) -> || | D14: ='Data Base Bule'!E15 -> 0 | E14: =CONCATENATE('Data Base Bule'!D15,"|",'Data Base Bule'!K15,"#",'Data Base Bule'!J15,"#",'Data Base Bule'!I15) -> |## | F14: =CONCATENATE("A","|","|",'Data Base Bule'!L15) -> A|| | G14: N/A | H14: =CONCATENATE('Data Base Bule'!M15,"###") -> ### | I14: OUR | J14: E0|N|199 | K14: N/A | L14: N/A | M14: remit.service09@gmail.com
A15: ='Data Base Bule'!R16 -> 0 | B15: =CONCATENATE('Data Base Bule'!R16,"|",'Data Base Bule'!C16,"|",'Data Base Bule'!S16,"|",'Data Base Bule'!T16,"|",'Data Base Bule'!U16,"|","|","ID","|","|","ID","|","|") -> ||||||ID||ID|| | C15: =CONCATENATE('Data Base Bule'!B16,"|",'Data Base Bule'!N16,"|",'Data Base Bule'!H16) -> || | D15: ='Data Base Bule'!E16 -> 0 | E15: =CONCATENATE('Data Base Bule'!D16,"|",'Data Base Bule'!K16,"#",'Data Base Bule'!J16,"#",'Data Base Bule'!I16) -> |## | F15: =CONCATENATE("A","|","|",'Data Base Bule'!L16) -> A|| | G15: N/A | H15: =CONCATENATE('Data Base Bule'!M16,"###") -> ### | I15: OUR | J15: E0|N|199 | K15: N/A | L15: N/A | M15: remit.service09@gmail.com
A16: ='Data Base Bule'!R17 -> 0 | B16: =CONCATENATE('Data Base Bule'!R17,"|",'Data Base Bule'!C17,"|",'Data Base Bule'!S17,"|",'Data Base Bule'!T17,"|",'Data Base Bule'!U17,"|","|","ID","|","|","ID","|","|") -> ||||||ID||ID|| | C16: =CONCATENATE('Data Base Bule'!B17,"|",'Data Base Bule'!N17,"|",'Data Base Bule'!H17) -> || | D16: ='Data Base Bule'!E17 -> 0 | E16: =CONCATENATE('Data Base Bule'!D17,"|",'Data Base Bule'!K17,"#",'Data Base Bule'!J17,"#",'Data Base Bule'!I17) -> |## | F16: =CONCATENATE("A","|","|",'Data Base Bule'!L17) -> A|| | G16: N/A | H16: =CONCATENATE('Data Base Bule'!M17,"###") -> ### | I16: OUR | J16: E0|N|199 | K16: N/A | L16: N/A | M16: remit.service09@gmail.com
A17: ='Data Base Bule'!R18 -> 0 | B17: =CONCATENATE('Data Base Bule'!R18,"|",'Data Base Bule'!C18,"|",'Data Base Bule'!S18,"|",'Data Base Bule'!T18,"|",'Data Base Bule'!U18,"|","|","ID","|","|","ID","|","|") -> ||||||ID||ID|| | C17: =CONCATENATE('Data Base Bule'!B18,"|",'Data Base Bule'!N18,"|",'Data Base Bule'!H18) -> || | D17: ='Data Base Bule'!E18 -> 0 | E17: =CONCATENATE('Data Base Bule'!D18,"|",'Data Base Bule'!K18,"#",'Data Base Bule'!J18,"#",'Data Base Bule'!I18) -> |## | F17: =CONCATENATE("A","|","|",'Data Base Bule'!L18) -> A|| | G17: N/A | H17: =CONCATENATE('Data Base Bule'!M18,"###") -> ### | I17: OUR | J17: E0|N|199 | K17: N/A | L17: N/A | M17: remit.service09@gmail.com
A18: ='Data Base Bule'!R19 -> 0 | B18: =CONCATENATE('Data Base Bule'!R19,"|",'Data Base Bule'!C19,"|",'Data Base Bule'!S19,"|",'Data Base Bule'!T19,"|",'Data Base Bule'!U19,"|","|","ID","|","|","ID","|","|") -> ||||||ID||ID|| | C18: =CONCATENATE('Data Base Bule'!B19,"|",'Data Base Bule'!N19,"|",'Data Base Bule'!H19) -> || | D18: ='Data Base Bule'!E19 -> 0 | E18: =CONCATENATE('Data Base Bule'!D19,"|",'Data Base Bule'!K19,"#",'Data Base Bule'!J19,"#",'Data Base Bule'!I19) -> |## | F18: =CONCATENATE("A","|","|",'Data Base Bule'!L19) -> A|| | G18: N/A | H18: =CONCATENATE('Data Base Bule'!M19,"###") -> ### | I18: OUR | J18: E0|N|199 | K18: N/A | L18: N/A | M18: remit.service09@gmail.com
A19: ='Data Base Bule'!R20 -> 0 | B19: =CONCATENATE('Data Base Bule'!R20,"|",'Data Base Bule'!C20,"|",'Data Base Bule'!S20,"|",'Data Base Bule'!T20,"|",'Data Base Bule'!U20,"|","|","ID","|","|","ID","|","|") -> ||||||ID||ID|| | C19: =CONCATENATE('Data Base Bule'!B20,"|",'Data Base Bule'!N20,"|",'Data Base Bule'!H20) -> || | D19: ='Data Base Bule'!E20 -> 0 | E19: =CONCATENATE('Data Base Bule'!D20,"|",'Data Base Bule'!K20,"#",'Data Base Bule'!J20,"#",'Data Base Bule'!I20) -> |## | F19: =CONCATENATE("A","|","|",'Data Base Bule'!L20) -> A|| | G19: N/A | H19: =CONCATENATE('Data Base Bule'!M20,"###") -> ### | I19: OUR | J19: E0|N|199 | K19: N/A | L19: N/A | M19: remit.service09@gmail.com
A20: ='Data Base Bule'!R21 -> 0 | B20: =CONCATENATE('Data Base Bule'!R21,"|",'Data Base Bule'!C21,"|",'Data Base Bule'!S21,"|",'Data Base Bule'!T21,"|",'Data Base Bule'!U21,"|","|","ID","|","|","ID","|","|") -> ||||||ID||ID|| | C20: =CONCATENATE('Data Base Bule'!B21,"|",'Data Base Bule'!N21,"|",'Data Base Bule'!H21) -> || | D20: ='Data Base Bule'!E21 -> 0 | E20: =CONCATENATE('Data Base Bule'!D21,"|",'Data Base Bule'!K21,"#",'Data Base Bule'!J21,"#",'Data Base Bule'!I21) -> |## | F20: =CONCATENATE("A","|","|",'Data Base Bule'!L21) -> A|| | G20: N/A | H20: =CONCATENATE('Data Base Bule'!M21,"###") -> ### | I20: OUR | J20: E0|N|199 | K20: N/A | L20: N/A | M20: remit.service09@gmail.com
... A49: ='Data Base Bule'!R50 -> 0 | B49: =CONCATENATE('Data Base Bule'!R50,"|",'Data Base Bule'!C50,"|",'Data Base Bule'!S50,"|",'Data Base Bule'!T50,"|",'Data Base Bule'!U50,"|","|","ID","|","|","ID","|","|") -> ||||||ID||ID|| | C49: =CONCATENATE('Data Base Bule'!B50,"|",'Data Base Bule'!N50,"|",'Data Base Bule'!H50) -> || | D49: ='Data Base Bule'!E50 -> 0 | E49: =CONCATENATE('Data Base Bule'!D50,"|",'Data Base Bule'!K50,"#",'Data Base Bule'!J50,"#",'Data Base Bule'!I50) -> |## | F49: =CONCATENATE("A","|","|",'Data Base Bule'!L50) -> A|| | G49: N/A | H49: =CONCATENATE('Data Base Bule'!M50,"###") -> ### | I49: OUR | J49: E0|N|199 | K49: N/A | L49: N/A | M49: remit.service09@gmail.com
A50: ='Data Base Bule'!R51 -> 0 | B50: =CONCATENATE('Data Base Bule'!R51,"|",'Data Base Bule'!C51,"|",'Data Base Bule'!S51,"|",'Data Base Bule'!T51,"|",'Data Base Bule'!U51,"|","|","ID","|","|","ID","|","|") -> ||||||ID||ID|| | C50: =CONCATENATE('Data Base Bule'!B51,"|",'Data Base Bule'!N51,"|",'Data Base Bule'!H51) -> || | D50: ='Data Base Bule'!E51 -> 0 | E50: =CONCATENATE('Data Base Bule'!D51,"|",'Data Base Bule'!K51,"#",'Data Base Bule'!J51,"#",'Data Base Bule'!I51) -> |## | F50: =CONCATENATE("A","|","|",'Data Base Bule'!L51) -> A|| | G50: N/A | H50: =CONCATENATE('Data Base Bule'!M51,"###") -> ### | I50: OUR | J50: E0|N|199
A51: ='Data Base Bule'!R52 -> 0 | B51: =CONCATENATE('Data Base Bule'!R52,"|",'Data Base Bule'!C52,"|",'Data Base Bule'!S52,"|",'Data Base Bule'!T52,"|",'Data Base Bule'!U52,"|","|","ID","|","|","ID","|","|") -> ||||||ID||ID|| | C51: =CONCATENATE('Data Base Bule'!B52,"|",'Data Base Bule'!N52,"|",'Data Base Bule'!H52) -> || | D51: ='Data Base Bule'!E52 -> 0 | E51: =CONCATENATE('Data Base Bule'!D52,"|",'Data Base Bule'!K52,"#",'Data Base Bule'!J52,"#",'Data Base Bule'!I52) -> |## | F51: =CONCATENATE("A","|","|",'Data Base Bule'!L52) -> A|| | G51: N/A | H51: =CONCATENATE('Data Base Bule'!M52,"###") -> ### | I51: OUR | J51: E0|N|199
A52: ='Data Base Bule'!R53 -> 0 | B52: =CONCATENATE('Data Base Bule'!R53,"|",'Data Base Bule'!C53,"|",'Data Base Bule'!S53,"|",'Data Base Bule'!T53,"|",'Data Base Bule'!U53,"|","|","ID","|","|","ID","|","|") -> ||||||ID||ID|| | C52: =CONCATENATE('Data Base Bule'!B53,"|",'Data Base Bule'!N53,"|",'Data Base Bule'!H53) -> || | D52: ='Data Base Bule'!E53 -> 0 | E52: =CONCATENATE('Data Base Bule'!D53,"|",'Data Base Bule'!K53,"#",'Data Base Bule'!J53,"#",'Data Base Bule'!I53) -> |## | F52: =CONCATENATE("A","|","|",'Data Base Bule'!L53) -> A|| | G52: N/A | H52: =CONCATENATE('Data Base Bule'!M53,"###") -> ### | I52: OUR | J52: E0|N|199
E53: =CONCATENATE('Data Base Bule'!D54,"|",'Data Base Bule'!K54,"#",'Data Base Bule'!J54,"#",'Data Base Bule'!I54) -> |## | F53: =CONCATENATE("A","|","|",'Data Base Bule'!L54) -> A|| | G53: N/A | H53: =CONCATENATE('Data Base Bule'!M54,"###") -> ### | I53: OUR | J53: E0|N|199

Sheet Data Base Bule
A1: 1 | B1: 2 | C1: 3 | D1: 4 | E1: 5 | F1: 6 | G1: 7 | H1: 8 | I1: 9 | J1: 10 | K1: 11 | L1: 12 | M1: 13 | N1: 14 | O1: 15 | P1: 16 | Q1: 17 | R1: 18 | S1: 19 | T1: 20 | U1: 21
A2: No. | B2: Date of Transaction | C2: Bill To (Payer) | D2: Beneficiary Name | E2: Account number of Beneficiary | F2: Beneficiary Bank | G2: City, Country of Bank Beneficiary | H2: Amounts | I2: Country of Beneficiary | J2: City of Beneficiary | K2: Complete Address of Beneficiary Account | L2: Swift | M2: Payment details 1 | N2: Currency | O2: Name correspondence Bank | P2: Swift Bank Corr | Q2: City, Country Bank Corr | R2: Nomor Rekening | S2: Alamat payer | T2: Kota Payer | U2: Negara Payer | X2: NAMA | Y2: ALAMAT | Z2: KOTA | AA2: NEGARA | AC2: NOMOR REKENING
AB3: NAMA PT | AC3: USD | AD3: EUR | AE3: CNY | AF3: AED | AG3: JPY | AH3: SGD | AI3: MYR | AJ3: GBP
A4: 1 | B4: 260701 | X4: PT JURITA AGROTAMA INDONESIA | Y4: Jl Setrasari Mega Square B 18 Sukagalih Sukajadi Bandung | Z4: BANDUNG | AA4: INDONESIA | AB4: PT JURITA AGROTAMA INDONESIA | AC4: 050202000015306 | AD4: 050218000005302 | AE4: 050229000002305 | AF4: 050228000002309
A5: 2 | B5: 260701 | X5: PT GEMA SAPTA BINTANG | Y5: Jln Hanjawar Pacet No 99 Cipendawa Cianjur | Z5: CIANJUR | AA5: INDONESIA | AB5: PT GEMA SAPTA BINTANG | AC5: 050202000016302 | AD5: 050218000006308 | AE5: 050229000003301 | AF5: 050228000003305
A6: 3 | B6: 260701 | X6: PT KAIROS SINERGI INDONESIA | Y6: Jln Siliwangi No 5B Pancoran Mas Depok | Z6: DEPOK | AA6: INDONESIA | AB6: PT KAIROS SINERGI INDONESIA | AC6: 050202000017308 | AD6: 050218000007304 | AE6: 050229000004307 | AF6: 050228000004301 | AG6: 050204000004307 | AH6: 050203000004301 | AJ6: 050205000006305
A7: 4 | B7: 260701 | X7: PT FABLE TEKNOLGI NUSANTARA | Y7: Menara Rajawali Lt 16 Jln Dr Ide Anak Agung Gde Agung Jakarta | Z7: JAKARTA | AA7: INDONESIA | AB7: PT FABLE TEKNOLGI NUSANTARA | AC7: 050202000014300 | AD7: 050218000004306 | AE7: 050229000001309 | AF7: 050228000001303
A8: 5 | B8: 260701 | X8: PT GOSYEN TRADE INTERNATIONAL | Y8: Menara Rajawali Lt 6 Jln Dr Ide Anak Agung Gde Agung Jakarta | Z8: JAKARTA | AA8: INDONESIA | AB8: PT GOSYEN TRADE INTERNATIONAL | AC8: 050202000019300 | AD8: 050218000010307 | AE8: 050229000007305 | AF8: 050228000007309
A9: 6 | B9: 260701 | X9: PT EKAWIRA FAZWAN SENTRAL | Y9: Menara Rajawali Lt 6 Jln Dr Ide Anak Agung Gde Agung Jakarta | Z9: JAKARTA | AA9: INDONESIA | AB9: PT EKAWIRA FAZWAN SENTRAL | AC9: 050202000020301 | AD9: 050218000009306 | AE9: 050229000010308 | AF9: 050228000005307
A10: 7 | X10: PT MERAPI SEMESTA INDONESIA | Y10: AXA Tower City Jln Prof Dr Satrio Kav 18 Karet Kuningan Jaksel | Z10: JAKARTA | AA10: INDONESIA | AB10: PT MERAPI SEMESTA INDONESIA | AC10: 050202000021307 | AD10: 050218000008300 | AE10: 050229000006309 | AF10: 050228000006303 | AG10: 050204000005303 | AI10: 050208000001507
A11: 8
A12: 9
A13: 10
A14: 11
A15: 12
A16: 13
A17: 14
A18: 15
A19: 16
A20: 17
A21: 18
A22: 19
... A53: 50

Sheet INV.1
A1: PAYMENT ORDER
A3: Filled by the customer
A4: VALUE DATE | B4: 29/04/2026
A6: AMOUNT * | B6: =VLOOKUP(1,'Data Base Bule'!$A$4:$U$20,8,0) -> 0
A8: currency * | B8: =VLOOKUP(1,'Data Base Bule'!$A$4:$U$22,14,0) -> 0
A10: BILL TO | B10: =VLOOKUP(1,'Data Base Bule'!$A$4:$U$20,3,0) -> 0
B11: =VLOOKUP(1,'Data Base Bule'!$A$4:$U$20,19,0) -> 0
A13: Beneficiary * | B13: =VLOOKUP(1,'Data Base Bule'!$A$4:$U$22,4,0) -> 0
A15: Beneficiary COUNTRY* | B15: =VLOOKUP(1,'Data Base Bule'!$A$4:$U$22,9,0) -> 0
A17: Beneficiary address * | B17: =VLOOKUP(1,'Data Base Bule'!$A$4:$U$22,11,0) -> 0
A19: ACCOUNT * | B19: =VLOOKUP(1,'Data Base Bule'!$A$4:$U$22,5,0) -> 0
A22: BENEF.BANK * | B22: =VLOOKUP(1,'Data Base Bule'!$A$4:$U$22,6,0) -> 0
A24: ADDRESS | B24: =VLOOKUP(1,'Data Base Bule'!$A$4:$U$20,7,0) -> 0
A25: Адрес банка получателя
A27: SWIFT * | B27: =VLOOKUP(1,'Data Base Bule'!$A$4:$U$22,12,0) -> 0
A29: BLZ, ABA, SORT CODE
A31: CORR.BANK
A33: ADDRESS
A35: SWIFT
A37: ACCOUNT
A39: PAYMENT DETAILS * | B39: =VLOOKUP(1,'Data Base Bule'!$A$4:$U$22,13,0) -> 0
A42: Commision | B42: OUR

Sheet INV.2
A1: PAYMENT ORDER
A3: Filled by the customer
A4: VALUE DATE | B4: 14/04/2026
A6: AMOUNT * | B6: =VLOOKUP(2,'Data Base Bule'!$A$4:$U$120,8,0) -> 0
A8: currency * | B8: =VLOOKUP(2,'Data Base Bule'!$A$4:$U$122,14,0) -> 0
A10: BILL TO | B10: =VLOOKUP(2,'Data Base Bule'!$A$4:$U$120,3,0) -> 0
B11: =VLOOKUP(2,'Data Base Bule'!$A$4:$U$120,19,0) -> 0
A13: Beneficiary * | B13: =VLOOKUP(2,'Data Base Bule'!$A$4:$U$122,4,0) -> 0
A15: Beneficiary COUNTRY* | B15: =VLOOKUP(2,'Data Base Bule'!$A$4:$U$122,9,0) -> 0
A17: Beneficiary address * | B17: =VLOOKUP(2,'Data Base Bule'!$A$4:$U$122,11,0) -> 0
A19: ACCOUNT * | B19: =VLOOKUP(2,'Data Base Bule'!$A$4:$U$122,5,0) -> 0
A22: BENEF.BANK * | B22: =VLOOKUP(2,'Data Base Bule'!$A$4:$U$122,6,0) -> 0
A24: ADDRESS | B24: =VLOOKUP(2,'Data Base Bule'!$A$4:$U$120,7,0) -> 0
A27: SWIFT * | B27: =VLOOKUP(2,'Data Base Bule'!$A$4:$U$122,12,0) -> 0
A29: BLZ, ABA, SORT CODE
A31: CORR.BANK
A33: ADDRESS
A35: SWIFT
A37: ACCOUNT
A39: PAYMENT DETAILS * | B39: =VLOOKUP(2,'Data Base Bule'!$A$4:$U$122,13,0) -> 0
A42: Commision | B42: OUR

Sheet INV.3
A1: Заявление на валютный перевод
A3: Заполняется клиентом
A4: VALUE DATE | B4: =VLOOKUP(3,'Data Base Bule'!$A$4:$U$217,2,0) -> 260701
A5: Дата платежа
A6: AMOUNT * | B6: =VLOOKUP(3,'Data Base Bule'!$A$4:$U$220,8,0) -> 0
A7: сумма
A8: currency * | B8: =VLOOKUP(3,'Data Base Bule'!$A$4:$U$222,14,0) -> 0
A9: валюта
A10: BILL TO | B10: =VLOOKUP(3,'Data Base Bule'!$A$4:$U$220,3,0) -> 0
B11: =VLOOKUP(3,'Data Base Bule'!$A$4:$U$220,19,0) -> 0
A13: Beneficiary * | B13: =VLOOKUP(3,'Data Base Bule'!$A$4:$U$222,4,0) -> 0
A14: получатель
A15: Beneficiary COUNTRY* | B15: =VLOOKUP(3,'Data Base Bule'!$A$4:$U$222,9,0) -> 0
A16: Страна получателя
A17: Beneficiary address * | B17: =VLOOKUP(3,'Data Base Bule'!$A$4:$U$222,11,0) -> 0
A18: Адрес получателя
A19: ACCOUNT * | B19: =VLOOKUP(3,'Data Base Bule'!$A$4:$U$222,5,0) -> 0
A20: Номер счета или IBAN код
A22: BENEF.BANK * | B22: =VLOOKUP(3,'Data Base Bule'!$A$4:$U$222,6,0) -> 0
A23: Банк получателя
A24: ADDRESS | B24: =VLOOKUP(3,'Data Base Bule'!$A$4:$U$220,7,0) -> 0
A25: Адрес банка получателя
A27: SWIFT * | B27: =VLOOKUP(3,'Data Base Bule'!$A$4:$U$222,12,0) -> 0
A28: Cвифт Банка получателя
A29: BLZ, ABA, SORT CODE
A31: CORR.BANK
A32: Банк корреспондент
A33: ADDRESS
A34: Адрес банка корреспондента
A35: SWIFT
A36: Свифт банка корреспондента
A37: ACCOUNT
A38: Счет банка получателя в банке корреспонденте
A39: PAYMENT DETAILS * | B39: =VLOOKUP(3,'Data Base Bule'!$A$4:$U$222,13,0) -> 0
A40: назначение платежа
A41: (обязательно указать категорию товара!)
A42: комиссия за счет | B42: OUR

Sheet INV.4
A1: Заявление на валютный перевод
A3: Заполняется клиентом
A4: VALUE DATE | B4: =VLOOKUP(4,'Data Base Bule'!$A$4:$U$317,2,0) -> 260701
A5: Дата платежа
A6: AMOUNT * | B6: =VLOOKUP(4,'Data Base Bule'!$A$4:$U$320,8,0) -> 0
A7: сумма
A8: currency * | B8: =VLOOKUP(4,'Data Base Bule'!$A$4:$U$322,14,0) -> 0
A9: валюта
A10: BILL TO | B10: =VLOOKUP(4,'Data Base Bule'!$A$4:$U$320,3,0) -> 0
B11: =VLOOKUP(4,'Data Base Bule'!$A$4:$U$320,19,0) -> 0
A13: Beneficiary * | B13: =VLOOKUP(4,'Data Base Bule'!$A$4:$U$322,4,0) -> 0
A14: получатель
A15: Beneficiary COUNTRY* | B15: =VLOOKUP(4,'Data Base Bule'!$A$4:$U$322,9,0) -> 0
A16: Страна получателя
A17: Beneficiary address * | B17: =VLOOKUP(4,'Data Base Bule'!$A$4:$U$322,11,0) -> 0
A18: Адрес получателя
A19: ACCOUNT * | B19: =VLOOKUP(4,'Data Base Bule'!$A$4:$U$322,5,0) -> 0
A20: Номер счета или IBAN код
A22: BENEF.BANK * | B22: =VLOOKUP(4,'Data Base Bule'!$A$4:$U$322,6,0) -> 0
A23: Банк получателя
A24: ADDRESS | B24: =VLOOKUP(4,'Data Base Bule'!$A$4:$U$320,7,0) -> 0
A25: Адрес банка получателя
A27: SWIFT * | B27: =VLOOKUP(4,'Data Base Bule'!$A$4:$U$322,12,0) -> 0
A28: Cвифт Банка получателя
A29: BLZ, ABA, SORT CODE
A31: CORR.BANK
A32: Банк корреспондент
A33: ADDRESS
A34: Адрес банка корреспондента
A35: SWIFT
A36: Свифт банка корреспондента
A37: ACCOUNT
A38: Счет банка получателя в банке корреспонденте
A39: PAYMENT DETAILS * | B39: =VLOOKUP(4,'Data Base Bule'!$A$4:$U$322,13,0) -> 0
A40: назначение платежа
A41: (обязательно указать категорию товара!)
A42: комиссия за счет | B42: OUR

Sheet INV.5
A1: Заявление на валютный перевод
A3: Заполняется клиентом
A4: VALUE DATE | B4: =VLOOKUP(5,'Data Base Bule'!$A$6:$U$417,5,0) -> 0
A5: Дата платежа
A6: AMOUNT * | B6: =VLOOKUP(5,'Data Base Bule'!$A$6:$U$422,8,0) -> 0
A7: сумма
A8: currency * | B8: =VLOOKUP(5,'Data Base Bule'!$A$6:$U$422,14,0) -> 0
A9: валюта
A10: BILL TO | B10: =VLOOKUP(5,'Data Base Bule'!$A$6:$U$422,3,0) -> 0
B11: =VLOOKUP(5,'Data Base Bule'!$A$6:$U$422,19,0) -> 0
A13: Beneficiary * | B13: =VLOOKUP(5,'Data Base Bule'!$A$6:$U$422,4,0) -> 0
A14: получатель
A15: Beneficiary COUNTRY* | B15: =VLOOKUP(5,'Data Base Bule'!$A$6:$U$422,9,0) -> 0
A16: Страна получателя
A17: Beneficiary address * | B17: =VLOOKUP(5,'Data Base Bule'!$A$6:$U$422,11,0) -> 0
A18: Адрес получателя
A19: ACCOUNT * | B19: =VLOOKUP(5,'Data Base Bule'!$A$6:$U$422,5,0) -> 0
A20: Номер счета или IBAN код
A22: BENEF.BANK * | B22: =VLOOKUP(5,'Data Base Bule'!$A$6:$U$422,6,0) -> 0
A23: Банк получателя
A24: ADDRESS | B24: =VLOOKUP(5,'Data Base Bule'!$A$6:$U$422,7,0) -> 0
A25: Адрес банка получателя
A27: SWIFT * | B27: =VLOOKUP(5,'Data Base Bule'!$A$6:$U$422,12,0) -> 0
A28: Cвифт Банка получателя
A29: BLZ, ABA, SORT CODE
A31: CORR.BANK
A32: Банк корреспондент
A33: ADDRESS
A34: Адрес банка корреспондента
A35: SWIFT
A36: Свифт банка корреспондента
A37: ACCOUNT
A38: Счет банка получателя в банке корреспонденте
A39: PAYMENT DETAILS * | B39: =VLOOKUP(5,'Data Base Bule'!$A$6:$U$422,13,0) -> 0
A40: назначение платежа
A41: (обязательно указать категорию товара!)
A42: комиссия за счет | B42: OUR

Sheet INV.6
A1: Заявление на валютный перевод
A3: Заполняется клиентом
A4: VALUE DATE | B4: =VLOOKUP(6,'Data Base Bule'!$A$4:$U$117,2,0) -> 260701
A5: Дата платежа
A6: AMOUNT * | B6: =VLOOKUP(6,'Data Base Bule'!$A$4:$U$520,8,0) -> 0
A7: сумма
A8: currency * | B8: =VLOOKUP(6,'Data Base Bule'!$A$4:$U$522,14,0) -> 0
A9: валюта
A10: BILL TO | B10: =VLOOKUP(6,'Data Base Bule'!$A$4:$U$520,3,0) -> 0
B11: =VLOOKUP(6,'Data Base Bule'!$A$4:$U$520,19,0) -> 0
A13: Beneficiary * | B13: =VLOOKUP(6,'Data Base Bule'!$A$4:$U$522,4,0) -> 0
A14: получатель
A15: Beneficiary COUNTRY* | B15: =VLOOKUP(6,'Data Base Bule'!$A$4:$U$522,9,0) -> 0
A16: Страна получателя
A17: Beneficiary address * | B17: =VLOOKUP(6,'Data Base Bule'!$A$4:$U$522,11,0) -> 0
A18: Адрес получателя
A19: ACCOUNT * | B19: =VLOOKUP(6,'Data Base Bule'!$A$4:$U$522,5,0) -> 0
A20: Номер счета или IBAN код
A22: BENEF.BANK * | B22: =VLOOKUP(6,'Data Base Bule'!$A$4:$U$522,6,0) -> 0
A23: Банк получателя
A24: ADDRESS | B24: =VLOOKUP(6,'Data Base Bule'!$A$4:$U$520,7,0) -> 0
A25: Адрес банка получателя
A27: SWIFT * | B27: =VLOOKUP(6,'Data Base Bule'!$A$4:$U$522,12,0) -> 0
A28: Cвифт Банка получателя
A29: BLZ, ABA, SORT CODE
A31: CORR.BANK
A32: Банк корреспондент
A33: ADDRESS
A34: Адрес банка корреспондента
A35: SWIFT
A36: Свифт банка корреспондента
A37: ACCOUNT
A38: Счет банка получателя в банке корреспонденте
A39: PAYMENT DETAILS * | B39: =VLOOKUP(6,'Data Base Bule'!$A$4:$U$522,13,0) -> 0
A40: назначение платежа
A41: (обязательно указать категорию товара!)
A42: комиссия за счет | B42: OUR

Sheet INV.7
A1: Заявление на валютный перевод
A3: Заполняется клиентом
A4: VALUE DATE | B4: =VLOOKUP(7,'Data Base Bule'!$A$4:$U$117,2,0) -> 0
A5: Дата платежа
A6: AMOUNT * | B6: =VLOOKUP(7,'Data Base Bule'!$A$4:$U$620,8,0) -> 0
A7: сумма
A8: currency * | B8: =VLOOKUP(7,'Data Base Bule'!$A$4:$U$622,14,0) -> 0
A9: валюта
A10: BILL TO | B10: =VLOOKUP(7,'Data Base Bule'!$A$4:$U$620,3,0) -> 0
B11: =VLOOKUP(7,'Data Base Bule'!$A$4:$U$620,19,0) -> 0
A13: Beneficiary * | B13: =VLOOKUP(7,'Data Base Bule'!$A$4:$U$622,4,0) -> 0
A14: получатель
A15: Beneficiary COUNTRY* | B15: =VLOOKUP(7,'Data Base Bule'!$A$4:$U$622,9,0) -> 0
A16: Страна получателя
A17: Beneficiary address * | B17: =VLOOKUP(7,'Data Base Bule'!$A$4:$U$622,11,0) -> 0
A18: Адрес получателя
A19: ACCOUNT * | B19: =VLOOKUP(7,'Data Base Bule'!$A$4:$U$622,5,0) -> 0
A20: Номер счета или IBAN код
A22: BENEF.BANK * | B22: =VLOOKUP(7,'Data Base Bule'!$A$4:$U$622,6,0) -> 0
A23: Банк получателя
A24: ADDRESS | B24: =VLOOKUP(7,'Data Base Bule'!$A$4:$U$620,7,0) -> 0
A25: Адрес банка получателя
A27: SWIFT * | B27: =VLOOKUP(7,'Data Base Bule'!$A$4:$U$622,12,0) -> 0
A28: Cвифт Банка получателя
A29: BLZ, ABA, SORT CODE
A31: CORR.BANK
A32: Банк корреспондент
A33: ADDRESS
A34: Адрес банка корреспондента
A35: SWIFT
A36: Свифт банка корреспондента
A37: ACCOUNT
A38: Счет банка получателя в банке корреспонденте
A39: PAYMENT DETAILS * | B39: =VLOOKUP(7,'Data Base Bule'!$A$4:$U$622,13,0) -> 0
A40: назначение платежа
A41: (обязательно указать категорию товара!)
A42: комиссия за счет | B42: OUR

Sheet INV.8
A1: Заявление на валютный перевод
A3: Заполняется клиентом
A4: VALUE DATE | B4: =VLOOKUP(8,'Data Base Bule'!$A$4:$U$117,2,0) -> 0
A5: Дата платежа
A6: AMOUNT * | B6: =VLOOKUP(8,'Data Base Bule'!$A$4:$U$720,8,0) -> 0
A7: сумма
A8: currency * | B8: =VLOOKUP(8,'Data Base Bule'!$A$4:$U$722,14,0) -> 0
A9: валюта
A10: BILL TO | B10: =VLOOKUP(8,'Data Base Bule'!$A$4:$U$720,3,0) -> 0
B11: =VLOOKUP(8,'Data Base Bule'!$A$4:$U$720,19,0) -> 0
A13: Beneficiary * | B13: =VLOOKUP(8,'Data Base Bule'!$A$4:$U$722,4,0) -> 0
A14: получатель
A15: Beneficiary COUNTRY* | B15: =VLOOKUP(8,'Data Base Bule'!$A$4:$U$722,9,0) -> 0
A16: Страна получателя
A17: Beneficiary address * | B17: =VLOOKUP(8,'Data Base Bule'!$A$4:$U$722,11,0) -> 0
A18: Адрес получателя
A19: ACCOUNT * | B19: =VLOOKUP(8,'Data Base Bule'!$A$4:$U$722,5,0) -> 0
A20: Номер счета или IBAN код
A22: BENEF.BANK * | B22: =VLOOKUP(8,'Data Base Bule'!$A$4:$U$722,6,0) -> 0
A23: Банк получателя
A24: ADDRESS | B24: =VLOOKUP(8,'Data Base Bule'!$A$4:$U$720,7,0) -> 0
A25: Адрес банка получателя
A27: SWIFT * | B27: =VLOOKUP(8,'Data Base Bule'!$A$4:$U$722,12,0) -> 0
A28: Cвифт Банка получателя
A29: BLZ, ABA, SORT CODE
A31: CORR.BANK
A32: Банк корреспондент
A33: ADDRESS
A34: Адрес банка корреспондента
A35: SWIFT
A36: Свифт банка корреспондента
A37: ACCOUNT
A38: Счет банка получателя в банке корреспонденте
A39: PAYMENT DETAILS * | B39: =VLOOKUP(8,'Data Base Bule'!$A$4:$U$722,13,0) -> 0
A40: назначение платежа
A41: (обязательно указать категорию товара!)
A42: комиссия за счет | B42: OUR

Sheet INV.9
A1: Заявление на валютный перевод
A3: Заполняется клиентом
A4: VALUE DATE | B4: =VLOOKUP(9,'Data Base Bule'!$A$4:$U$117,2,0) -> 0
A5: Дата платежа
A6: AMOUNT * | B6: =VLOOKUP(9,'Data Base Bule'!$A$4:$U$820,8,0) -> 0
A7: сумма
A8: currency * | B8: =VLOOKUP(9,'Data Base Bule'!$A$4:$U$822,14,0) -> 0
A9: валюта
A10: BILL TO | B10: =VLOOKUP(9,'Data Base Bule'!$A$4:$U$820,3,0) -> 0
B11: =VLOOKUP(9,'Data Base Bule'!$A$4:$U$820,19,0) -> 0
A13: Beneficiary * | B13: =VLOOKUP(9,'Data Base Bule'!$A$4:$U$822,4,0) -> 0
A14: получатель
A15: Beneficiary COUNTRY* | B15: =VLOOKUP(9,'Data Base Bule'!$A$4:$U$822,9,0) -> 0
A16: Страна получателя
A17: Beneficiary address * | B17: =VLOOKUP(9,'Data Base Bule'!$A$4:$U$822,11,0) -> 0
A18: Адрес получателя
A19: ACCOUNT * | B19: =VLOOKUP(9,'Data Base Bule'!$A$4:$U$822,5,0) -> 0
A20: Номер счета или IBAN код
A22: BENEF.BANK * | B22: =VLOOKUP(9,'Data Base Bule'!$A$4:$U$822,6,0) -> 0
A23: Банк получателя
A24: ADDRESS | B24: =VLOOKUP(9,'Data Base Bule'!$A$4:$U$820,7,0) -> 0
A25: Адрес банка получателя
A27: SWIFT * | B27: =VLOOKUP(9,'Data Base Bule'!$A$4:$U$822,12,0) -> 0
A28: Cвифт Банка получателя
A29: BLZ, ABA, SORT CODE
A31: CORR.BANK
A32: Банк корреспондент
A33: ADDRESS
A34: Адрес банка корреспондента
A35: SWIFT
A36: Свифт банка корреспондента
A37: ACCOUNT
A38: Счет банка получателя в банке корреспонденте
A39: PAYMENT DETAILS * | B39: =VLOOKUP(9,'Data Base Bule'!$A$4:$U$822,13,0) -> 0
A40: назначение платежа
A41: (обязательно указать категорию товара!)
A42: комиссия за счет | B42: OUR

Sheet INV.10
A1: Заявление на валютный перевод
A3: Заполняется клиентом
A4: VALUE DATE | B4: =VLOOKUP(10,'Data Base Bule'!$A$4:$U$117,2,0) -> 0
A5: Дата платежа
A6: AMOUNT * | B6: =VLOOKUP(10,'Data Base Bule'!$A$4:$U$920,8,0) -> 0
A7: сумма
A8: currency * | B8: =VLOOKUP(10,'Data Base Bule'!$A$4:$U$922,14,0) -> 0
A9: валюта
A10: BILL TO | B10: =VLOOKUP(10,'Data Base Bule'!$A$4:$U$920,3,0) -> 0
B11: =VLOOKUP(10,'Data Base Bule'!$A$4:$U$920,19,0) -> 0
A13: Beneficiary * | B13: =VLOOKUP(10,'Data Base Bule'!$A$4:$U$922,4,0) -> 0
A14: получатель
A15: Beneficiary COUNTRY* | B15: =VLOOKUP(10,'Data Base Bule'!$A$4:$U$922,9,0) -> 0
A16: Страна получателя
A17: Beneficiary address * | B17: =VLOOKUP(10,'Data Base Bule'!$A$4:$U$922,11,0) -> 0
A18: Адрес получателя
A19: ACCOUNT * | B19: =VLOOKUP(10,'Data Base Bule'!$A$4:$U$922,5,0) -> 0
A20: Номер счета или IBAN код
A22: BENEF.BANK * | B22: =VLOOKUP(10,'Data Base Bule'!$A$4:$U$922,6,0) -> 0
A23: Банк получателя
A24: ADDRESS | B24: =VLOOKUP(10,'Data Base Bule'!$A$4:$U$920,7,0) -> 0
A25: Адрес банка получателя
A27: SWIFT * | B27: =VLOOKUP(10,'Data Base Bule'!$A$4:$U$922,12,0) -> 0
A28: Cвифт Банка получателя
A29: BLZ, ABA, SORT CODE
A31: CORR.BANK
A32: Банк корреспондент
A33: ADDRESS
A34: Адрес банка корреспондента
A35: SWIFT
A36: Свифт банка корреспондента
A37: ACCOUNT
A38: Счет банка получателя в банке корреспонденте
A39: PAYMENT DETAILS * | B39: =VLOOKUP(10,'Data Base Bule'!$A$4:$U$922,13,0) -> 0
A40: назначение платежа
A41: (обязательно указать категорию товара!)
A42: комиссия за счет | B42: OUR

Sheet INV.11
A1: Заявление на валютный перевод
A3: Заполняется клиентом
A4: VALUE DATE | B4: =VLOOKUP(11,'Data Base Bule'!$A$4:$U$117,2,0) -> 0
A5: Дата платежа
A6: AMOUNT * | B6: =VLOOKUP(11,'Data Base Bule'!$A$4:$U$1020,8,0) -> 0
A7: сумма
A8: currency * | B8: =VLOOKUP(11,'Data Base Bule'!$A$4:$U$1022,14,0) -> 0
A9: валюта
A10: BILL TO | B10: =VLOOKUP(11,'Data Base Bule'!$A$4:$U$1020,3,0) -> 0
B11: =VLOOKUP(11,'Data Base Bule'!$A$4:$U$1020,19,0) -> 0
A13: Beneficiary * | B13: =VLOOKUP(11,'Data Base Bule'!$A$4:$U$1022,4,0) -> 0
A14: получатель
A15: Beneficiary COUNTRY* | B15: =VLOOKUP(11,'Data Base Bule'!$A$4:$U$1022,9,0) -> 0
A16: Страна получателя
A17: Beneficiary address * | B17: =VLOOKUP(11,'Data Base Bule'!$A$4:$U$1022,11,0) -> 0
A18: Адрес получателя
A19: ACCOUNT * | B19: =VLOOKUP(11,'Data Base Bule'!$A$4:$U$1022,5,0) -> 0
A20: Номер счета или IBAN код
A22: BENEF.BANK * | B22: =VLOOKUP(11,'Data Base Bule'!$A$4:$U$1022,6,0) -> 0
A23: Банк получателя
A24: ADDRESS | B24: =VLOOKUP(11,'Data Base Bule'!$A$4:$U$1020,7,0) -> 0
A25: Адрес банка получателя
A27: SWIFT * | B27: =VLOOKUP(11,'Data Base Bule'!$A$4:$U$1022,12,0) -> 0
A28: Cвифт Банка получателя
A29: BLZ, ABA, SORT CODE
A31: CORR.BANK
A32: Банк корреспондент
A33: ADDRESS
A34: Адрес банка корреспондента
A35: SWIFT
A36: Свифт банка корреспондента
A37: ACCOUNT
A38: Счет банка получателя в банке корреспонденте
A39: PAYMENT DETAILS * | B39: =VLOOKUP(11,'Data Base Bule'!$A$4:$U$1022,13,0) -> 0
A40: назначение платежа
A41: (обязательно указать категорию товара!)
A42: комиссия за счет | B42: OUR

Sheet INV.12
A1: Заявление на валютный перевод
A3: Заполняется клиентом
A4: VALUE DATE | B4: =VLOOKUP(12,'Data Base Bule'!$A$4:$U$117,2,0) -> 0
A5: Дата платежа
A6: AMOUNT * | B6: =VLOOKUP(12,'Data Base Bule'!$A$4:$U$1120,8,0) -> 0
A7: сумма
A8: currency * | B8: =VLOOKUP(12,'Data Base Bule'!$A$4:$U$1122,14,0) -> 0
A9: валюта
A10: BILL TO | B10: =VLOOKUP(12,'Data Base Bule'!$A$4:$U$1120,3,0) -> 0
B11: =VLOOKUP(12,'Data Base Bule'!$A$4:$U$1120,19,0) -> 0
A13: Beneficiary * | B13: =VLOOKUP(12,'Data Base Bule'!$A$4:$U$1122,4,0) -> 0
A14: получатель
A15: Beneficiary COUNTRY* | B15: =VLOOKUP(12,'Data Base Bule'!$A$4:$U$1122,9,0) -> 0
A16: Страна получателя
A17: Beneficiary address * | B17: =VLOOKUP(12,'Data Base Bule'!$A$4:$U$1122,11,0) -> 0
A18: Адрес получателя
A19: ACCOUNT * | B19: =VLOOKUP(12,'Data Base Bule'!$A$4:$U$1122,5,0) -> 0
A20: Номер счета или IBAN код
A22: BENEF.BANK * | B22: =VLOOKUP(12,'Data Base Bule'!$A$4:$U$1122,6,0) -> 0
A23: Банк получателя
A24: ADDRESS | B24: =VLOOKUP(12,'Data Base Bule'!$A$4:$U$1120,7,0) -> 0
A25: Адрес банка получателя
A27: SWIFT * | B27: =VLOOKUP(12,'Data Base Bule'!$A$4:$U$1122,12,0) -> 0
A28: Cвифт Банка получателя
A29: BLZ, ABA, SORT CODE
A31: CORR.BANK
A32: Банк корреспондент
A33: ADDRESS
A34: Адрес банка корреспондента
A35: SWIFT
A36: Свифт банка корреспондента
A37: ACCOUNT
A38: Счет банка получателя в банке корреспонденте
A39: PAYMENT DETAILS * | B39: =VLOOKUP(12,'Data Base Bule'!$A$4:$U$1122,13,0) -> 0
A40: назначение платежа
A41: (обязательно указать категорию товара!)
A42: комиссия за счет | B42: OUR

Sheet INV.13
A1: Заявление на валютный перевод
A3: Заполняется клиентом
A4: VALUE DATE | B4: =VLOOKUP(13,'Data Base Bule'!$A$4:$U$117,2,0) -> 0
A5: Дата платежа
A6: AMOUNT * | B6: =VLOOKUP(13,'Data Base Bule'!$A$4:$U$1220,8,0) -> 0
A7: сумма
A8: currency * | B8: =VLOOKUP(13,'Data Base Bule'!$A$4:$U$1222,14,0) -> 0
A9: валюта
A10: BILL TO | B10: =VLOOKUP(13,'Data Base Bule'!$A$4:$U$1220,3,0) -> 0
B11: =VLOOKUP(13,'Data Base Bule'!$A$4:$U$1220,19,0) -> 0
A13: Beneficiary * | B13: =VLOOKUP(13,'Data Base Bule'!$A$4:$U$1222,4,0) -> 0
A14: получатель
A15: Beneficiary COUNTRY* | B15: =VLOOKUP(13,'Data Base Bule'!$A$4:$U$1222,9,0) -> 0
A16: Страна получателя
A17: Beneficiary address * | B17: =VLOOKUP(13,'Data Base Bule'!$A$4:$U$1222,11,0) -> 0
A18: Адрес получателя
A19: ACCOUNT * | B19: =VLOOKUP(13,'Data Base Bule'!$A$4:$U$1222,5,0) -> 0
A20: Номер счета или IBAN код
A22: BENEF.BANK * | B22: =VLOOKUP(13,'Data Base Bule'!$A$4:$U$1222,6,0) -> 0
A23: Банк получателя
A24: ADDRESS | B24: =VLOOKUP(13,'Data Base Bule'!$A$4:$U$1220,7,0) -> 0
A25: Адрес банка получателя
A27: SWIFT * | B27: =VLOOKUP(13,'Data Base Bule'!$A$4:$U$1222,12,0) -> 0
A28: Cвифт Банка получателя
A29: BLZ, ABA, SORT CODE
A31: CORR.BANK
A32: Банк корреспондент
A33: ADDRESS
A34: Адрес банка корреспондента
A35: SWIFT
A36: Свифт банка корреспондента
A37: ACCOUNT
A38: Счет банка получателя в банке корреспонденте
A39: PAYMENT DETAILS * | B39: =VLOOKUP(13,'Data Base Bule'!$A$4:$U$1222,13,0) -> 0
A40: назначение платежа
A41: (обязательно указать категорию товара!)
A42: комиссия за счет | B42: OUR

Sheet INV.14
A1: Заявление на валютный перевод
A3: Заполняется клиентом
A4: VALUE DATE | B4: =VLOOKUP(14,'Data Base Bule'!$A$4:$U$117,2,0) -> 0
A5: Дата платежа
A6: AMOUNT * | B6: =VLOOKUP(14,'Data Base Bule'!$A$4:$U$1320,8,0) -> 0
A7: сумма
A8: currency * | B8: =VLOOKUP(14,'Data Base Bule'!$A$4:$U$1322,14,0) -> 0
A9: валюта
A10: BILL TO | B10: =VLOOKUP(14,'Data Base Bule'!$A$4:$U$1320,3,0) -> 0
B11: =VLOOKUP(14,'Data Base Bule'!$A$4:$U$1320,19,0) -> 0
A13: Beneficiary * | B13: =VLOOKUP(14,'Data Base Bule'!$A$4:$U$1322,4,0) -> 0
A14: получатель
A15: Beneficiary COUNTRY* | B15: =VLOOKUP(14,'Data Base Bule'!$A$4:$U$1322,9,0) -> 0
A16: Страна получателя
A17: Beneficiary address * | B17: =VLOOKUP(14,'Data Base Bule'!$A$4:$U$1322,11,0) -> 0
A18: Адрес получателя
A19: ACCOUNT * | B19: =VLOOKUP(14,'Data Base Bule'!$A$4:$U$1322,5,0) -> 0
A20: Номер счета или IBAN код
A22: BENEF.BANK * | B22: =VLOOKUP(14,'Data Base Bule'!$A$4:$U$1322,6,0) -> 0
A23: Банк получателя
A24: ADDRESS | B24: =VLOOKUP(14,'Data Base Bule'!$A$4:$U$1320,7,0) -> 0
A25: Адрес банка получателя
A27: SWIFT * | B27: =VLOOKUP(14,'Data Base Bule'!$A$4:$U$1322,12,0) -> 0
A28: Cвифт Банка получателя
A29: BLZ, ABA, SORT CODE
A31: CORR.BANK
A32: Банк корреспондент
A33: ADDRESS
A34: Адрес банка корреспондента
A35: SWIFT
A36: Свифт банка корреспондента
A37: ACCOUNT
A38: Счет банка получателя в банке корреспонденте
A39: PAYMENT DETAILS * | B39: =VLOOKUP(14,'Data Base Bule'!$A$4:$U$1322,13,0) -> 0
A40: назначение платежа
A41: (обязательно указать категорию товара!)
A42: комиссия за счет | B42: OUR

Sheet INV.15
A1: Заявление на валютный перевод
A3: Заполняется клиентом
A4: VALUE DATE | B4: =VLOOKUP(15,'Data Base Bule'!$A$4:$U$117,2,0) -> 0
A5: Дата платежа
A6: AMOUNT * | B6: =VLOOKUP(15,'Data Base Bule'!$A$4:$U$1420,8,0) -> 0
A7: сумма
A8: currency * | B8: =VLOOKUP(15,'Data Base Bule'!$A$4:$U$1422,14,0) -> 0
A9: валюта
A10: BILL TO | B10: =VLOOKUP(15,'Data Base Bule'!$A$4:$U$1420,3,0) -> 0
B11: =VLOOKUP(15,'Data Base Bule'!$A$4:$U$1420,19,0) -> 0
A13: Beneficiary * | B13: =VLOOKUP(15,'Data Base Bule'!$A$4:$U$1422,4,0) -> 0
A14: получатель
A15: Beneficiary COUNTRY* | B15: =VLOOKUP(15,'Data Base Bule'!$A$4:$U$1422,9,0) -> 0
A16: Страна получателя
A17: Beneficiary address * | B17: =VLOOKUP(15,'Data Base Bule'!$A$4:$U$1422,11,0) -> 0
A18: Адрес получателя
A19: ACCOUNT * | B19: =VLOOKUP(15,'Data Base Bule'!$A$4:$U$1422,5,0) -> 0
A20: Номер счета или IBAN код
A22: BENEF.BANK * | B22: =VLOOKUP(15,'Data Base Bule'!$A$4:$U$1422,6,0) -> 0
A23: Банк получателя
A24: ADDRESS | B24: =VLOOKUP(15,'Data Base Bule'!$A$4:$U$1420,7,0) -> 0
A25: Адрес банка получателя
A27: SWIFT * | B27: =VLOOKUP(15,'Data Base Bule'!$A$4:$U$1422,12,0) -> 0
A28: Cвифт Банка получателя
A29: BLZ, ABA, SORT CODE
A31: CORR.BANK
A32: Банк корреспондент
A33: ADDRESS
A34: Адрес банка корреспондента
A35: SWIFT
A36: Свифт банка корреспондента
A37: ACCOUNT
A38: Счет банка получателя в банке корреспонденте
A39: PAYMENT DETAILS * | B39: =VLOOKUP(15,'Data Base Bule'!$A$4:$U$1422,13,0) -> 0
A40: назначение платежа
A41: (обязательно указать категорию товара!)
A42: комиссия за счет | B42: OUR

Sheet INV.16
A1: Заявление на валютный перевод
A3: Заполняется клиентом
A4: VALUE DATE | B4: =VLOOKUP(16,'Data Base Bule'!$A$4:$U$117,2,0) -> 0
A5: Дата платежа
A6: AMOUNT * | B6: =VLOOKUP(16,'Data Base Bule'!$A$4:$U$1520,8,0) -> 0
A7: сумма
A8: currency * | B8: =VLOOKUP(16,'Data Base Bule'!$A$4:$U$1522,14,0) -> 0
A9: валюта
A10: BILL TO | B10: =VLOOKUP(16,'Data Base Bule'!$A$4:$U$1520,3,0) -> 0
B11: =VLOOKUP(16,'Data Base Bule'!$A$4:$U$1520,19,0) -> 0
A13: Beneficiary * | B13: =VLOOKUP(16,'Data Base Bule'!$A$4:$U$1522,4,0) -> 0
A14: получатель
A15: Beneficiary COUNTRY* | B15: =VLOOKUP(16,'Data Base Bule'!$A$4:$U$1522,9,0) -> 0
A16: Страна получателя
A17: Beneficiary address * | B17: =VLOOKUP(16,'Data Base Bule'!$A$4:$U$1522,11,0) -> 0
A18: Адрес получателя
A19: ACCOUNT * | B19: =VLOOKUP(16,'Data Base Bule'!$A$4:$U$1522,5,0) -> 0
A20: Номер счета или IBAN код
A22: BENEF.BANK * | B22: =VLOOKUP(16,'Data Base Bule'!$A$4:$U$1522,6,0) -> 0
A23: Банк получателя
A24: ADDRESS | B24: =VLOOKUP(16,'Data Base Bule'!$A$4:$U$1520,7,0) -> 0
A25: Адрес банка получателя
A27: SWIFT * | B27: =VLOOKUP(16,'Data Base Bule'!$A$4:$U$1522,12,0) -> 0
A28: Cвифт Банка получателя
A29: BLZ, ABA, SORT CODE
A31: CORR.BANK
A32: Банк корреспондент
A33: ADDRESS
A34: Адрес банка корреспондента
A35: SWIFT
A36: Свифт банка корреспондента
A37: ACCOUNT
A38: Счет банка получателя в банке корреспонденте
A39: PAYMENT DETAILS * | B39: =VLOOKUP(16,'Data Base Bule'!$A$4:$U$1522,13,0) -> 0
A40: назначение платежа
A41: (обязательно указать категорию товара!)
A42: комиссия за счет | B42: OUR

Sheet INV.17
A1: Заявление на валютный перевод
A3: Заполняется клиентом
A4: VALUE DATE | B4: =VLOOKUP(17,'Data Base Bule'!$A$4:$U$117,2,0) -> 0
A5: Дата платежа
A6: AMOUNT * | B6: =VLOOKUP(17,'Data Base Bule'!$A$4:$U$1620,8,0) -> 0
A7: сумма
A8: currency * | B8: =VLOOKUP(17,'Data Base Bule'!$A$4:$U$1622,14,0) -> 0
A9: валюта
A10: BILL TO | B10: =VLOOKUP(17,'Data Base Bule'!$A$4:$U$1620,3,0) -> 0
B11: =VLOOKUP(17,'Data Base Bule'!$A$4:$U$1620,19,0) -> 0
A13: Beneficiary * | B13: =VLOOKUP(17,'Data Base Bule'!$A$4:$U$1622,4,0) -> 0
A14: получатель
A15: Beneficiary COUNTRY* | B15: =VLOOKUP(17,'Data Base Bule'!$A$4:$U$1622,9,0) -> 0
A16: Страна получателя
A17: Beneficiary address * | B17: =VLOOKUP(17,'Data Base Bule'!$A$4:$U$1622,11,0) -> 0
A18: Адрес получателя
A19: ACCOUNT * | B19: =VLOOKUP(17,'Data Base Bule'!$A$4:$U$1622,5,0) -> 0
A20: Номер счета или IBAN код
A22: BENEF.BANK * | B22: =VLOOKUP(17,'Data Base Bule'!$A$4:$U$1622,6,0) -> 0
A23: Банк получателя
A24: ADDRESS | B24: =VLOOKUP(17,'Data Base Bule'!$A$4:$U$1620,7,0) -> 0
A25: Адрес банка получателя
A27: SWIFT * | B27: =VLOOKUP(17,'Data Base Bule'!$A$4:$U$1622,12,0) -> 0
A28: Cвифт Банка получателя
A29: BLZ, ABA, SORT CODE
A31: CORR.BANK
A32: Банк корреспондент
A33: ADDRESS
A34: Адрес банка корреспондента
A35: SWIFT
A36: Свифт банка корреспондента
A37: ACCOUNT
A38: Счет банка получателя в банке корреспонденте
A39: PAYMENT DETAILS * | B39: =VLOOKUP(17,'Data Base Bule'!$A$4:$U$1622,13,0) -> 0
A40: назначение платежа
A41: (обязательно указать категорию товара!)
A42: комиссия за счет | B42: OUR

Sheet INV.18
A1: Заявление на валютный перевод
A3: Заполняется клиентом
A4: VALUE DATE | B4: =VLOOKUP(18,'Data Base Bule'!$A$4:$U$117,2,0) -> 0
A5: Дата платежа
A6: AMOUNT * | B6: =VLOOKUP(18,'Data Base Bule'!$A$4:$U$1720,8,0) -> 0
A7: сумма
A8: currency * | B8: =VLOOKUP(18,'Data Base Bule'!$A$4:$U$1722,14,0) -> 0
A9: валюта
A10: BILL TO | B10: =VLOOKUP(18,'Data Base Bule'!$A$4:$U$1720,3,0) -> 0
B11: =VLOOKUP(18,'Data Base Bule'!$A$4:$U$1720,19,0) -> 0
A13: Beneficiary * | B13: =VLOOKUP(18,'Data Base Bule'!$A$4:$U$1722,4,0) -> 0
A14: получатель
A15: Beneficiary COUNTRY* | B15: =VLOOKUP(18,'Data Base Bule'!$A$4:$U$1722,9,0) -> 0
A16: Страна получателя
A17: Beneficiary address * | B17: =VLOOKUP(18,'Data Base Bule'!$A$4:$U$1722,11,0) -> 0
A18: Адрес получателя
A19: ACCOUNT * | B19: =VLOOKUP(18,'Data Base Bule'!$A$4:$U$1722,5,0) -> 0
A20: Номер счета или IBAN код
A22: BENEF.BANK * | B22: =VLOOKUP(18,'Data Base Bule'!$A$4:$U$1722,6,0) -> 0
A23: Банк получателя
A24: ADDRESS | B24: =VLOOKUP(18,'Data Base Bule'!$A$4:$U$1720,7,0) -> 0
A25: Адрес банка получателя
A27: SWIFT * | B27: =VLOOKUP(18,'Data Base Bule'!$A$4:$U$1722,12,0) -> 0
A28: Cвифт Банка получателя
A29: BLZ, ABA, SORT CODE
A31: CORR.BANK
A32: Банк корреспондент
A33: ADDRESS
A34: Адрес банка корреспондента
A35: SWIFT
A36: Свифт банка корреспондента
A37: ACCOUNT
A38: Счет банка получателя в банке корреспонденте
A39: PAYMENT DETAILS * | B39: =VLOOKUP(18,'Data Base Bule'!$A$4:$U$1722,13,0) -> 0
A40: назначение платежа
A41: (обязательно указать категорию товара!)
A42: комиссия за счет | B42: OUR

Sheet INV.19
A1: Заявление на валютный перевод
A3: Заполняется клиентом
A4: VALUE DATE | B4: =VLOOKUP(19,'Data Base Bule'!$A$4:$U$117,2,0) -> 0
A5: Дата платежа
A6: AMOUNT * | B6: =VLOOKUP(19,'Data Base Bule'!$A$4:$U$1820,8,0) -> 0
A7: сумма
A8: currency * | B8: =VLOOKUP(19,'Data Base Bule'!$A$4:$U$1822,14,0) -> 0
A9: валюта
A10: BILL TO | B10: =VLOOKUP(19,'Data Base Bule'!$A$4:$U$1820,3,0) -> 0
B11: =VLOOKUP(19,'Data Base Bule'!$A$4:$U$1820,19,0) -> 0
A13: Beneficiary * | B13: =VLOOKUP(19,'Data Base Bule'!$A$4:$U$1822,4,0) -> 0
A14: получатель
A15: Beneficiary COUNTRY* | B15: =VLOOKUP(19,'Data Base Bule'!$A$4:$U$1822,9,0) -> 0
A16: Страна получателя
A17: Beneficiary address * | B17: =VLOOKUP(19,'Data Base Bule'!$A$4:$U$1822,11,0) -> 0
A18: Адрес получателя
A19: ACCOUNT * | B19: =VLOOKUP(19,'Data Base Bule'!$A$4:$U$1822,5,0) -> 0
A20: Номер счета или IBAN код
A22: BENEF.BANK * | B22: =VLOOKUP(19,'Data Base Bule'!$A$4:$U$1822,6,0) -> 0
A23: Банк получателя
A24: ADDRESS | B24: =VLOOKUP(19,'Data Base Bule'!$A$4:$U$1820,7,0) -> 0
A25: Адрес банка получателя
A27: SWIFT * | B27: =VLOOKUP(19,'Data Base Bule'!$A$4:$U$1822,12,0) -> 0
A28: Cвифт Банка получателя
A29: BLZ, ABA, SORT CODE
A31: CORR.BANK
A32: Банк корреспондент
A33: ADDRESS
A34: Адрес банка корреспондента
A35: SWIFT
A36: Свифт банка корреспондента
A37: ACCOUNT
A38: Счет банка получателя в банке корреспонденте
A39: PAYMENT DETAILS * | B39: =VLOOKUP(19,'Data Base Bule'!$A$4:$U$1822,13,0) -> 0
A40: назначение платежа
A41: (обязательно указать категорию товара!)
A42: комиссия за счет | B42: OUR

Sheet INV.20
A1: Заявление на валютный перевод
A3: Заполняется клиентом
A4: VALUE DATE | B4: =VLOOKUP(20,'Data Base Bule'!$A$4:$U$117,2,0) -> 0
A5: Дата платежа
A6: AMOUNT * | B6: =VLOOKUP(20,'Data Base Bule'!$A$4:$U$1920,8,0) -> 0
A7: сумма
A8: currency * | B8: =VLOOKUP(20,'Data Base Bule'!$A$4:$U$1922,14,0) -> 0
A9: валюта
A10: BILL TO | B10: =VLOOKUP(20,'Data Base Bule'!$A$4:$U$1920,3,0) -> 0
B11: =VLOOKUP(20,'Data Base Bule'!$A$4:$U$1920,19,0) -> 0
A13: Beneficiary * | B13: =VLOOKUP(20,'Data Base Bule'!$A$4:$U$1922,4,0) -> 0
A14: получатель
A15: Beneficiary COUNTRY* | B15: =VLOOKUP(20,'Data Base Bule'!$A$4:$U$1922,9,0) -> 0
A16: Страна получателя
A17: Beneficiary address * | B17: =VLOOKUP(20,'Data Base Bule'!$A$4:$U$1922,11,0) -> 0
A18: Адрес получателя
A19: ACCOUNT * | B19: =VLOOKUP(20,'Data Base Bule'!$A$4:$U$1922,5,0) -> 0
A20: Номер счета или IBAN код
A22: BENEF.BANK * | B22: =VLOOKUP(20,'Data Base Bule'!$A$4:$U$1922,6,0) -> 0
A23: Банк получателя
A24: ADDRESS | B24: =VLOOKUP(20,'Data Base Bule'!$A$4:$U$1920,7,0) -> 0
A25: Адрес банка получателя
A27: SWIFT * | B27: =VLOOKUP(20,'Data Base Bule'!$A$4:$U$1922,12,0) -> 0
A28: Cвифт Банка получателя
A29: BLZ, ABA, SORT CODE
A31: CORR.BANK
A32: Банк корреспондент
A33: ADDRESS
A34: Адрес банка корреспондента
A35: SWIFT
A36: Свифт банка корреспондента
A37: ACCOUNT
A38: Счет банка получателя в банке корреспонденте
A39: PAYMENT DETAILS * | B39: =VLOOKUP(20,'Data Base Bule'!$A$4:$U$1922,13,0) -> 0
A40: назначение платежа
A41: (обязательно указать категорию товара!)
A42: комиссия за счет | B42: OUR

Sheet INV.21
A1: Заявление на валютный перевод
A3: Заполняется клиентом
A4: VALUE DATE | B4: =VLOOKUP(21,'Data Base Bule'!$A$4:$U$117,2,0) -> 0
A5: Дата платежа
A6: AMOUNT * | B6: =VLOOKUP(21,'Data Base Bule'!$A$4:$U$2020,8,0) -> 0
A7: сумма
A8: currency * | B8: =VLOOKUP(21,'Data Base Bule'!$A$4:$U$2022,14,0) -> 0
A9: валюта
A10: BILL TO | B10: =VLOOKUP(21,'Data Base Bule'!$A$4:$U$2020,3,0) -> 0
B11: =VLOOKUP(21,'Data Base Bule'!$A$4:$U$2020,19,0) -> 0
A13: Beneficiary * | B13: =VLOOKUP(21,'Data Base Bule'!$A$4:$U$2022,4,0) -> 0
A14: получатель
A15: Beneficiary COUNTRY* | B15: =VLOOKUP(21,'Data Base Bule'!$A$4:$U$2022,9,0) -> 0
A16: Страна получателя
A17: Beneficiary address * | B17: =VLOOKUP(21,'Data Base Bule'!$A$4:$U$2022,11,0) -> 0
A18: Адрес получателя
A19: ACCOUNT * | B19: =VLOOKUP(21,'Data Base Bule'!$A$4:$U$2022,5,0) -> 0
A20: Номер счета или IBAN код
A22: BENEF.BANK * | B22: =VLOOKUP(21,'Data Base Bule'!$A$4:$U$2022,6,0) -> 0
A23: Банк получателя
A24: ADDRESS | B24: =VLOOKUP(21,'Data Base Bule'!$A$4:$U$2020,7,0) -> 0
A25: Адрес банка получателя
A27: SWIFT * | B27: =VLOOKUP(21,'Data Base Bule'!$A$4:$U$2022,12,0) -> 0
A28: Cвифт Банка получателя
A29: BLZ, ABA, SORT CODE
A31: CORR.BANK
A32: Банк корреспондент
A33: ADDRESS
A34: Адрес банка корреспондента
A35: SWIFT
A36: Свифт банка корреспондента
A37: ACCOUNT
A38: Счет банка получателя в банке корреспонденте
A39: PAYMENT DETAILS * | B39: =VLOOKUP(21,'Data Base Bule'!$A$4:$U$2022,13,0) -> 0
A40: назначение платежа
A41: (обязательно указать категорию товара!)
A42: комиссия за счет | B42: OUR

Sheet INV.22
A1: Заявление на валютный перевод
A3: Заполняется клиентом
A4: VALUE DATE | B4: =VLOOKUP(22,'Data Base Bule'!$A$4:$U$117,2,0) -> 0
A5: Дата платежа
A6: AMOUNT * | B6: =VLOOKUP(22,'Data Base Bule'!$A$4:$U$2120,8,0) -> 0
A7: сумма
A8: currency * | B8: =VLOOKUP(22,'Data Base Bule'!$A$4:$U$2122,14,0) -> 0
A9: валюта
A10: BILL TO | B10: =VLOOKUP(22,'Data Base Bule'!$A$4:$U$2120,3,0) -> 0
B11: =VLOOKUP(22,'Data Base Bule'!$A$4:$U$2120,19,0) -> 0
A13: Beneficiary * | B13: =VLOOKUP(22,'Data Base Bule'!$A$4:$U$2122,4,0) -> 0
A14: получатель
A15: Beneficiary COUNTRY* | B15: =VLOOKUP(22,'Data Base Bule'!$A$4:$U$2122,9,0) -> 0
A16: Страна получателя
A17: Beneficiary address * | B17: =VLOOKUP(22,'Data Base Bule'!$A$4:$U$2122,11,0) -> 0
A18: Адрес получателя
A19: ACCOUNT * | B19: =VLOOKUP(22,'Data Base Bule'!$A$4:$U$2122,5,0) -> 0
A20: Номер счета или IBAN код
A22: BENEF.BANK * | B22: =VLOOKUP(22,'Data Base Bule'!$A$4:$U$2122,6,0) -> 0
A23: Банк получателя
A24: ADDRESS | B24: =VLOOKUP(22,'Data Base Bule'!$A$4:$U$2120,7,0) -> 0
A25: Адрес банка получателя
A27: SWIFT * | B27: =VLOOKUP(22,'Data Base Bule'!$A$4:$U$2122,12,0) -> 0
A28: Cвифт Банка получателя
A29: BLZ, ABA, SORT CODE
A31: CORR.BANK
A32: Банк корреспондент
A33: ADDRESS
A34: Адрес банка корреспондента
A35: SWIFT
A36: Свифт банка корреспондента
A37: ACCOUNT
A38: Счет банка получателя в банке корреспонденте
A39: PAYMENT DETAILS * | B39: =VLOOKUP(22,'Data Base Bule'!$A$4:$U$2122,13,0) -> 0
A40: назначение платежа
A41: (обязательно указать категорию товара!)
A42: комиссия за счет | B42: OUR

Sheet INV.23
A1: Заявление на валютный перевод
A3: Заполняется клиентом
A4: VALUE DATE | B4: =VLOOKUP(23,'Data Base Bule'!$A$4:$U$117,2,0) -> 0
A5: Дата платежа
A6: AMOUNT * | B6: =VLOOKUP(23,'Data Base Bule'!$A$4:$U$2220,8,0) -> 0
A7: сумма
A8: currency * | B8: =VLOOKUP(23,'Data Base Bule'!$A$4:$U$2222,14,0) -> 0
A9: валюта
A10: BILL TO | B10: =VLOOKUP(23,'Data Base Bule'!$A$4:$U$2220,3,0) -> 0
B11: =VLOOKUP(23,'Data Base Bule'!$A$4:$U$2220,19,0) -> 0
A13: Beneficiary * | B13: =VLOOKUP(23,'Data Base Bule'!$A$4:$U$2222,4,0) -> 0
A14: получатель
A15: Beneficiary COUNTRY* | B15: =VLOOKUP(23,'Data Base Bule'!$A$4:$U$2222,9,0) -> 0
A16: Страна получателя
A17: Beneficiary address * | B17: =VLOOKUP(23,'Data Base Bule'!$A$4:$U$2222,11,0) -> 0
A18: Адрес получателя
A19: ACCOUNT * | B19: =VLOOKUP(23,'Data Base Bule'!$A$4:$U$2222,5,0) -> 0
A20: Номер счета или IBAN код
A22: BENEF.BANK * | B22: =VLOOKUP(23,'Data Base Bule'!$A$4:$U$2222,6,0) -> 0
A23: Банк получателя
A24: ADDRESS | B24: =VLOOKUP(23,'Data Base Bule'!$A$4:$U$2220,7,0) -> 0
A25: Адрес банка получателя
A27: SWIFT * | B27: =VLOOKUP(23,'Data Base Bule'!$A$4:$U$2222,12,0) -> 0
A28: Cвифт Банка получателя
A29: BLZ, ABA, SORT CODE
A31: CORR.BANK
A32: Банк корреспондент
A33: ADDRESS
A34: Адрес банка корреспондента
A35: SWIFT
A36: Свифт банка корреспондента
A37: ACCOUNT
A38: Счет банка получателя в банке корреспонденте
A39: PAYMENT DETAILS * | B39: =VLOOKUP(23,'Data Base Bule'!$A$4:$U$2222,13,0) -> 0
A40: назначение платежа
A41: (обязательно указать категорию товара!)
A42: комиссия за счет | B42: OUR

Sheet INV.24
A1: Заявление на валютный перевод
A3: Заполняется клиентом
A4: VALUE DATE | B4: =VLOOKUP(24,'Data Base Bule'!$A$4:$U$117,2,0) -> 0
A5: Дата платежа
A6: AMOUNT * | B6: =VLOOKUP(24,'Data Base Bule'!$A$4:$U$2320,8,0) -> 0
A7: сумма
A8: currency * | B8: =VLOOKUP(24,'Data Base Bule'!$A$4:$U$2322,14,0) -> 0
A9: валюта
A10: BILL TO | B10: =VLOOKUP(24,'Data Base Bule'!$A$4:$U$2320,3,0) -> 0
B11: =VLOOKUP(24,'Data Base Bule'!$A$4:$U$2320,19,0) -> 0
A13: Beneficiary * | B13: =VLOOKUP(24,'Data Base Bule'!$A$4:$U$2322,4,0) -> 0
A14: получатель
A15: Beneficiary COUNTRY* | B15: =VLOOKUP(24,'Data Base Bule'!$A$4:$U$2322,9,0) -> 0
A16: Страна получателя
A17: Beneficiary address * | B17: =VLOOKUP(24,'Data Base Bule'!$A$4:$U$2322,11,0) -> 0
A18: Адрес получателя
A19: ACCOUNT * | B19: =VLOOKUP(24,'Data Base Bule'!$A$4:$U$2322,5,0) -> 0
A20: Номер счета или IBAN код
A22: BENEF.BANK * | B22: =VLOOKUP(24,'Data Base Bule'!$A$4:$U$2322,6,0) -> 0
A23: Банк получателя
A24: ADDRESS | B24: =VLOOKUP(24,'Data Base Bule'!$A$4:$U$2320,7,0) -> 0
A25: Адрес банка получателя
A27: SWIFT * | B27: =VLOOKUP(24,'Data Base Bule'!$A$4:$U$2322,12,0) -> 0
A28: Cвифт Банка получателя
A29: BLZ, ABA, SORT CODE
A31: CORR.BANK
A32: Банк корреспондент
A33: ADDRESS
A34: Адрес банка корреспондента
A35: SWIFT
A36: Свифт банка корреспондента
A37: ACCOUNT
A38: Счет банка получателя в банке корреспонденте
A39: PAYMENT DETAILS * | B39: =VLOOKUP(24,'Data Base Bule'!$A$4:$U$2322,13,0) -> 0
A40: назначение платежа
A41: (обязательно указать категорию товара!)
A42: комиссия за счет | B42: OUR

Sheet INV.25
A1: Заявление на валютный перевод
A3: Заполняется клиентом
A4: VALUE DATE | B4: =VLOOKUP(25,'Data Base Bule'!$A$4:$U$117,2,0) -> 0
A5: Дата платежа
A6: AMOUNT * | B6: =VLOOKUP(25,'Data Base Bule'!$A$4:$U$2420,8,0) -> 0
A7: сумма
A8: currency * | B8: =VLOOKUP(25,'Data Base Bule'!$A$4:$U$2422,14,0) -> 0
A9: валюта
A10: BILL TO | B10: =VLOOKUP(25,'Data Base Bule'!$A$4:$U$2420,3,0) -> 0
B11: =VLOOKUP(25,'Data Base Bule'!$A$4:$U$2420,19,0) -> 0
A13: Beneficiary * | B13: =VLOOKUP(25,'Data Base Bule'!$A$4:$U$2422,4,0) -> 0
A14: получатель
A15: Beneficiary COUNTRY* | B15: =VLOOKUP(25,'Data Base Bule'!$A$4:$U$2422,9,0) -> 0
A16: Страна получателя
A17: Beneficiary address * | B17: =VLOOKUP(25,'Data Base Bule'!$A$4:$U$2422,11,0) -> 0
A18: Адрес получателя
A19: ACCOUNT * | B19: =VLOOKUP(25,'Data Base Bule'!$A$4:$U$2422,5,0) -> 0
A20: Номер счета или IBAN код
A22: BENEF.BANK * | B22: =VLOOKUP(25,'Data Base Bule'!$A$4:$U$2422,6,0) -> 0
A23: Банк получателя
A24: ADDRESS | B24: =VLOOKUP(25,'Data Base Bule'!$A$4:$U$2420,7,0) -> 0
A25: Адрес банка получателя
A27: SWIFT * | B27: =VLOOKUP(25,'Data Base Bule'!$A$4:$U$2422,12,0) -> 0
A28: Cвифт Банка получателя
A29: BLZ, ABA, SORT CODE
A31: CORR.BANK
A32: Банк корреспондент
A33: ADDRESS
A34: Адрес банка корреспондента
A35: SWIFT
A36: Свифт банка корреспондента
A37: ACCOUNT
A38: Счет банка получателя в банке корреспонденте
A39: PAYMENT DETAILS * | B39: =VLOOKUP(25,'Data Base Bule'!$A$4:$U$2422,13,0) -> 0
A40: назначение платежа
A41: (обязательно указать категорию товара!)
A42: комиссия за счет | B42: OUR

Sheet INV.26
A1: Заявление на валютный перевод
A3: Заполняется клиентом
A4: VALUE DATE | B4: =VLOOKUP(26,'Data Base Bule'!$A$4:$U$117,2,0) -> 0
A5: Дата платежа
A6: AMOUNT * | B6: =VLOOKUP(26,'Data Base Bule'!$A$4:$U$2520,8,0) -> 0
A7: сумма
A8: currency * | B8: =VLOOKUP(26,'Data Base Bule'!$A$4:$U$2522,14,0) -> 0
A9: валюта
A10: BILL TO | B10: =VLOOKUP(26,'Data Base Bule'!$A$4:$U$2520,3,0) -> 0
B11: =VLOOKUP(26,'Data Base Bule'!$A$4:$U$2520,19,0) -> 0
A13: Beneficiary * | B13: =VLOOKUP(26,'Data Base Bule'!$A$4:$U$2522,4,0) -> 0
A14: получатель
A15: Beneficiary COUNTRY* | B15: =VLOOKUP(26,'Data Base Bule'!$A$4:$U$2522,9,0) -> 0
A16: Страна получателя
A17: Beneficiary address * | B17: =VLOOKUP(26,'Data Base Bule'!$A$4:$U$2522,11,0) -> 0
A18: Адрес получателя
A19: ACCOUNT * | B19: =VLOOKUP(26,'Data Base Bule'!$A$4:$U$2522,5,0) -> 0
A20: Номер счета или IBAN код
A22: BENEF.BANK * | B22: =VLOOKUP(26,'Data Base Bule'!$A$4:$U$2522,6,0) -> 0
A23: Банк получателя
A24: ADDRESS | B24: =VLOOKUP(26,'Data Base Bule'!$A$4:$U$2520,7,0) -> 0
A25: Адрес банка получателя
A27: SWIFT * | B27: =VLOOKUP(26,'Data Base Bule'!$A$4:$U$2522,12,0) -> 0
A28: Cвифт Банка получателя
A29: BLZ, ABA, SORT CODE
A31: CORR.BANK
A32: Банк корреспондент
A33: ADDRESS
A34: Адрес банка корреспондента
A35: SWIFT
A36: Свифт банка корреспондента
A37: ACCOUNT
A38: Счет банка получателя в банке корреспонденте
A39: PAYMENT DETAILS * | B39: =VLOOKUP(26,'Data Base Bule'!$A$4:$U$2522,13,0) -> 0
A40: назначение платежа
A41: (обязательно указать категорию товара!)
A42: комиссия за счет | B42: OUR

Sheet INV.27
A1: Заявление на валютный перевод
A3: Заполняется клиентом
A4: VALUE DATE | B4: =VLOOKUP(27,'Data Base Bule'!$A$4:$U$117,2,0) -> 0
A5: Дата платежа
A6: AMOUNT * | B6: =VLOOKUP(27,'Data Base Bule'!$A$4:$U$2620,8,0) -> 0
A7: сумма
A8: currency * | B8: =VLOOKUP(27,'Data Base Bule'!$A$4:$U$2622,14,0) -> 0
A9: валюта
A10: BILL TO | B10: =VLOOKUP(27,'Data Base Bule'!$A$4:$U$2620,3,0) -> 0
B11: =VLOOKUP(27,'Data Base Bule'!$A$4:$U$2620,19,0) -> 0
A13: Beneficiary * | B13: =VLOOKUP(27,'Data Base Bule'!$A$4:$U$2622,4,0) -> 0
A14: получатель
A15: Beneficiary COUNTRY* | B15: =VLOOKUP(27,'Data Base Bule'!$A$4:$U$2622,9,0) -> 0
A16: Страна получателя
A17: Beneficiary address * | B17: =VLOOKUP(27,'Data Base Bule'!$A$4:$U$2622,11,0) -> 0
A18: Адрес получателя
A19: ACCOUNT * | B19: =VLOOKUP(27,'Data Base Bule'!$A$4:$U$2622,5,0) -> 0
A20: Номер счета или IBAN код
A22: BENEF.BANK * | B22: =VLOOKUP(27,'Data Base Bule'!$A$4:$U$2622,6,0) -> 0
A23: Банк получателя
A24: ADDRESS | B24: =VLOOKUP(27,'Data Base Bule'!$A$4:$U$2620,7,0) -> 0
A25: Адрес банка получателя
A27: SWIFT * | B27: =VLOOKUP(27,'Data Base Bule'!$A$4:$U$2622,12,0) -> 0
